Traceback (most recent call last):
  File "/home/aurora/AI/venv/bin/uvicorn", line 7, in <module>
    sys.exit(main())
             ^^^^^^
  File "/home/aurora/AI/venv/lib/python3.12/site-packages/click/core.py", line 1442, in __call__
    return self.main(*args, **kwargs)
           ^^^^^^^^^^^^^^^^^^^^^^^^^^
  File "/home/aurora/AI/venv/lib/python3.12/site-packages/click/core.py", line 1363, in main
    rv = self.invoke(ctx)
         ^^^^^^^^^^^^^^^^
  File "/home/aurora/AI/venv/lib/python3.12/site-packages/click/core.py", line 1226, in invoke
    return ctx.invoke(self.callback, **ctx.params)
           ^^^^^^^^^^^^^^^^^^^^^^^^^^^^^^^^^^^^^^^
  File "/home/aurora/AI/venv/lib/python3.12/site-packages/click/core.py", line 794, in invoke
    return callback(*args, **kwargs)
           ^^^^^^^^^^^^^^^^^^^^^^^^^
  File "/home/aurora/AI/venv/lib/python3.12/site-packages/uvicorn/main.py", line 413, in main
    run(
  File "/home/aurora/AI/venv/lib/python3.12/site-packages/uvicorn/main.py", line 580, in run
    server.run()
  File "/home/aurora/AI/venv/lib/python3.12/site-packages/uvicorn/server.py", line 67, in run
    return asyncio.run(self.serve(sockets=sockets))
           ^^^^^^^^^^^^^^^^^^^^^^^^^^^^^^^^^^^^^^^^
  File "/usr/lib/python3.12/asyncio/runners.py", line 194, in run
    return runner.run(main)
           ^^^^^^^^^^^^^^^^
  File "/usr/lib/python3.12/asyncio/runners.py", line 118, in run
    return self._loop.run_until_complete(task)
           ^^^^^^^^^^^^^^^^^^^^^^^^^^^^^^^^^^^
  File "uvloop/loop.pyx", line 1518, in uvloop.loop.Loop.run_until_complete
  File "/home/aurora/AI/venv/lib/python3.12/site-packages/uvicorn/server.py", line 71, in serve
    await self._serve(sockets)
  File "/home/aurora/AI/venv/lib/python3.12/site-packages/uvicorn/server.py", line 78, in _serve
    config.load()
  File "/home/aurora/AI/venv/lib/python3.12/site-packages/uvicorn/config.py", line 436, in load
    self.loaded_app = import_from_string(self.app)
                      ^^^^^^^^^^^^^^^^^^^^^^^^^^^^
  File "/home/aurora/AI/venv/lib/python3.12/site-packages/uvicorn/importer.py", line 19, in import_from_string
    module = importlib.import_module(module_str)
             ^^^^^^^^^^^^^^^^^^^^^^^^^^^^^^^^^^^
  File "/usr/lib/python3.12/importlib/__init__.py", line 90, in import_module
    return _bootstrap._gcd_import(name[level:], package, level)
           ^^^^^^^^^^^^^^^^^^^^^^^^^^^^^^^^^^^^^^^^^^^^^^^^^^^^
  File "<frozen importlib._bootstrap>", line 1387, in _gcd_import
  File "<frozen importlib._bootstrap>", line 1360, in _find_and_load
  File "<frozen importlib._bootstrap>", line 1331, in _find_and_load_unlocked
  File "<frozen importlib._bootstrap>", line 935, in _load_unlocked
  File "<frozen importlib._bootstrap_external>", line 991, in exec_module
  File "<frozen importlib._bootstrap_external>", line 1129, in get_code
  File "<frozen importlib._bootstrap_external>", line 1059, in source_to_code
  File "<frozen importlib._bootstrap>", line 488, in _call_with_frames_removed
  File "/home/aurora/AI/engine/api.py", line 62
    async def tick_once():
              ^^^^^
SyntaxError: invalid syntax
Traceback (most recent call last):
  File "/home/aurora/AI/venv/bin/uvicorn", line 7, in <module>
    sys.exit(main())
             ^^^^^^
  File "/home/aurora/AI/venv/lib/python3.12/site-packages/click/core.py", line 1442, in __call__
    return self.main(*args, **kwargs)
           ^^^^^^^^^^^^^^^^^^^^^^^^^^
  File "/home/aurora/AI/venv/lib/python3.12/site-packages/click/core.py", line 1363, in main
    rv = self.invoke(ctx)
         ^^^^^^^^^^^^^^^^
  File "/home/aurora/AI/venv/lib/python3.12/site-packages/click/core.py", line 1226, in invoke
    return ctx.invoke(self.callback, **ctx.params)
           ^^^^^^^^^^^^^^^^^^^^^^^^^^^^^^^^^^^^^^^
  File "/home/aurora/AI/venv/lib/python3.12/site-packages/click/core.py", line 794, in invoke
    return callback(*args, **kwargs)
           ^^^^^^^^^^^^^^^^^^^^^^^^^
  File "/home/aurora/AI/venv/lib/python3.12/site-packages/uvicorn/main.py", line 413, in main
    run(
  File "/home/aurora/AI/venv/lib/python3.12/site-packages/uvicorn/main.py", line 580, in run
    server.run()
  File "/home/aurora/AI/venv/lib/python3.12/site-packages/uvicorn/server.py", line 67, in run
    return asyncio.run(self.serve(sockets=sockets))
           ^^^^^^^^^^^^^^^^^^^^^^^^^^^^^^^^^^^^^^^^
  File "/usr/lib/python3.12/asyncio/runners.py", line 194, in run
    return runner.run(main)
           ^^^^^^^^^^^^^^^^
  File "/usr/lib/python3.12/asyncio/runners.py", line 118, in run
    return self._loop.run_until_complete(task)
           ^^^^^^^^^^^^^^^^^^^^^^^^^^^^^^^^^^^
  File "uvloop/loop.pyx", line 1518, in uvloop.loop.Loop.run_until_complete
  File "/home/aurora/AI/venv/lib/python3.12/site-packages/uvicorn/server.py", line 71, in serve
    await self._serve(sockets)
  File "/home/aurora/AI/venv/lib/python3.12/site-packages/uvicorn/server.py", line 78, in _serve
    config.load()
  File "/home/aurora/AI/venv/lib/python3.12/site-packages/uvicorn/config.py", line 436, in load
    self.loaded_app = import_from_string(self.app)
                      ^^^^^^^^^^^^^^^^^^^^^^^^^^^^
  File "/home/aurora/AI/venv/lib/python3.12/site-packages/uvicorn/importer.py", line 19, in import_from_string
    module = importlib.import_module(module_str)
             ^^^^^^^^^^^^^^^^^^^^^^^^^^^^^^^^^^^
  File "/usr/lib/python3.12/importlib/__init__.py", line 90, in import_module
    return _bootstrap._gcd_import(name[level:], package, level)
           ^^^^^^^^^^^^^^^^^^^^^^^^^^^^^^^^^^^^^^^^^^^^^^^^^^^^
  File "<frozen importlib._bootstrap>", line 1387, in _gcd_import
  File "<frozen importlib._bootstrap>", line 1360, in _find_and_load
  File "<frozen importlib._bootstrap>", line 1331, in _find_and_load_unlocked
  File "<frozen importlib._bootstrap>", line 935, in _load_unlocked
  File "<frozen importlib._bootstrap_external>", line 995, in exec_module
  File "<frozen importlib._bootstrap>", line 488, in _call_with_frames_removed
  File "/home/aurora/AI/engine/api.py", line 7, in <module>
    from . import ticker
  File "/home/aurora/AI/engine/ticker.py", line 17
    async def tick_once() -> Dict[str, Any]:
              ^^^^^
SyntaxError: invalid syntax
Traceback (most recent call last):
  File "/home/aurora/AI/venv/bin/uvicorn", line 7, in <module>
    sys.exit(main())
             ^^^^^^
  File "/home/aurora/AI/venv/lib/python3.12/site-packages/click/core.py", line 1442, in __call__
    return self.main(*args, **kwargs)
           ^^^^^^^^^^^^^^^^^^^^^^^^^^
  File "/home/aurora/AI/venv/lib/python3.12/site-packages/click/core.py", line 1363, in main
    rv = self.invoke(ctx)
         ^^^^^^^^^^^^^^^^
  File "/home/aurora/AI/venv/lib/python3.12/site-packages/click/core.py", line 1226, in invoke
    return ctx.invoke(self.callback, **ctx.params)
           ^^^^^^^^^^^^^^^^^^^^^^^^^^^^^^^^^^^^^^^
  File "/home/aurora/AI/venv/lib/python3.12/site-packages/click/core.py", line 794, in invoke
    return callback(*args, **kwargs)
           ^^^^^^^^^^^^^^^^^^^^^^^^^
  File "/home/aurora/AI/venv/lib/python3.12/site-packages/uvicorn/main.py", line 413, in main
    run(
  File "/home/aurora/AI/venv/lib/python3.12/site-packages/uvicorn/main.py", line 580, in run
    server.run()
  File "/home/aurora/AI/venv/lib/python3.12/site-packages/uvicorn/server.py", line 67, in run
    return asyncio.run(self.serve(sockets=sockets))
           ^^^^^^^^^^^^^^^^^^^^^^^^^^^^^^^^^^^^^^^^
  File "/usr/lib/python3.12/asyncio/runners.py", line 194, in run
    return runner.run(main)
           ^^^^^^^^^^^^^^^^
  File "/usr/lib/python3.12/asyncio/runners.py", line 118, in run
    return self._loop.run_until_complete(task)
           ^^^^^^^^^^^^^^^^^^^^^^^^^^^^^^^^^^^
  File "uvloop/loop.pyx", line 1518, in uvloop.loop.Loop.run_until_complete
  File "/home/aurora/AI/venv/lib/python3.12/site-packages/uvicorn/server.py", line 71, in serve
    await self._serve(sockets)
  File "/home/aurora/AI/venv/lib/python3.12/site-packages/uvicorn/server.py", line 78, in _serve
    config.load()
  File "/home/aurora/AI/venv/lib/python3.12/site-packages/uvicorn/config.py", line 436, in load
    self.loaded_app = import_from_string(self.app)
                      ^^^^^^^^^^^^^^^^^^^^^^^^^^^^
  File "/home/aurora/AI/venv/lib/python3.12/site-packages/uvicorn/importer.py", line 19, in import_from_string
    module = importlib.import_module(module_str)
             ^^^^^^^^^^^^^^^^^^^^^^^^^^^^^^^^^^^
  File "/usr/lib/python3.12/importlib/__init__.py", line 90, in import_module
    return _bootstrap._gcd_import(name[level:], package, level)
           ^^^^^^^^^^^^^^^^^^^^^^^^^^^^^^^^^^^^^^^^^^^^^^^^^^^^
  File "<frozen importlib._bootstrap>", line 1387, in _gcd_import
  File "<frozen importlib._bootstrap>", line 1360, in _find_and_load
  File "<frozen importlib._bootstrap>", line 1331, in _find_and_load_unlocked
  File "<frozen importlib._bootstrap>", line 935, in _load_unlocked
  File "<frozen importlib._bootstrap_external>", line 995, in exec_module
  File "<frozen importlib._bootstrap>", line 488, in _call_with_frames_removed
  File "/home/aurora/AI/engine/api.py", line 153, in <module>
    @app.get("/ai/readiness")
                                                    ^^^^^^
NameError: name 'secure' is not defined
Traceback (most recent call last):
  File "/home/aurora/AI/venv/bin/uvicorn", line 7, in <module>
    sys.exit(main())
             ^^^^^^
  File "/home/aurora/AI/venv/lib/python3.12/site-packages/click/core.py", line 1442, in __call__
    return self.main(*args, **kwargs)
           ^^^^^^^^^^^^^^^^^^^^^^^^^^
  File "/home/aurora/AI/venv/lib/python3.12/site-packages/click/core.py", line 1363, in main
    rv = self.invoke(ctx)
         ^^^^^^^^^^^^^^^^
  File "/home/aurora/AI/venv/lib/python3.12/site-packages/click/core.py", line 1226, in invoke
    return ctx.invoke(self.callback, **ctx.params)
           ^^^^^^^^^^^^^^^^^^^^^^^^^^^^^^^^^^^^^^^
  File "/home/aurora/AI/venv/lib/python3.12/site-packages/click/core.py", line 794, in invoke
    return callback(*args, **kwargs)
           ^^^^^^^^^^^^^^^^^^^^^^^^^
  File "/home/aurora/AI/venv/lib/python3.12/site-packages/uvicorn/main.py", line 413, in main
    run(
  File "/home/aurora/AI/venv/lib/python3.12/site-packages/uvicorn/main.py", line 580, in run
    server.run()
  File "/home/aurora/AI/venv/lib/python3.12/site-packages/uvicorn/server.py", line 67, in run
    return asyncio.run(self.serve(sockets=sockets))
           ^^^^^^^^^^^^^^^^^^^^^^^^^^^^^^^^^^^^^^^^
  File "/usr/lib/python3.12/asyncio/runners.py", line 194, in run
    return runner.run(main)
           ^^^^^^^^^^^^^^^^
  File "/usr/lib/python3.12/asyncio/runners.py", line 118, in run
    return self._loop.run_until_complete(task)
           ^^^^^^^^^^^^^^^^^^^^^^^^^^^^^^^^^^^
  File "uvloop/loop.pyx", line 1518, in uvloop.loop.Loop.run_until_complete
  File "/home/aurora/AI/venv/lib/python3.12/site-packages/uvicorn/server.py", line 71, in serve
    await self._serve(sockets)
  File "/home/aurora/AI/venv/lib/python3.12/site-packages/uvicorn/server.py", line 78, in _serve
    config.load()
  File "/home/aurora/AI/venv/lib/python3.12/site-packages/uvicorn/config.py", line 436, in load
    self.loaded_app = import_from_string(self.app)
                      ^^^^^^^^^^^^^^^^^^^^^^^^^^^^
  File "/home/aurora/AI/venv/lib/python3.12/site-packages/uvicorn/importer.py", line 19, in import_from_string
    module = importlib.import_module(module_str)
             ^^^^^^^^^^^^^^^^^^^^^^^^^^^^^^^^^^^
  File "/usr/lib/python3.12/importlib/__init__.py", line 90, in import_module
    return _bootstrap._gcd_import(name[level:], package, level)
           ^^^^^^^^^^^^^^^^^^^^^^^^^^^^^^^^^^^^^^^^^^^^^^^^^^^^
  File "<frozen importlib._bootstrap>", line 1387, in _gcd_import
  File "<frozen importlib._bootstrap>", line 1360, in _find_and_load
  File "<frozen importlib._bootstrap>", line 1331, in _find_and_load_unlocked
  File "<frozen importlib._bootstrap>", line 935, in _load_unlocked
  File "<frozen importlib._bootstrap_external>", line 995, in exec_module
  File "<frozen importlib._bootstrap>", line 488, in _call_with_frames_removed
  File "/home/aurora/AI/engine/api.py", line 153, in <module>
    @app.get("/ai/readiness")
                                                    ^^^^^^
NameError: name 'secure' is not defined
INFO:     Started server process [1300242]
INFO:     Waiting for application startup.
INFO:     Application startup complete.
INFO:     Uvicorn running on http://0.0.0.0:8000 (Press CTRL+C to quit)
ERROR:    Exception in ASGI application
Traceback (most recent call last):
  File "/home/aurora/AI/venv/lib/python3.12/site-packages/uvicorn/protocols/http/httptools_impl.py", line 401, in run_asgi
    result = await app(  # type: ignore[func-returns-value]
             ^^^^^^^^^^^^^^^^^^^^^^^^^^^^^^^^^^^^^^^^^^^^^^
  File "/home/aurora/AI/venv/lib/python3.12/site-packages/uvicorn/middleware/proxy_headers.py", line 70, in __call__
    return await self.app(scope, receive, send)
           ^^^^^^^^^^^^^^^^^^^^^^^^^^^^^^^^^^^^
  File "/home/aurora/AI/venv/lib/python3.12/site-packages/fastapi/applications.py", line 1054, in __call__
    await super().__call__(scope, receive, send)
  File "/home/aurora/AI/venv/lib/python3.12/site-packages/starlette/applications.py", line 113, in __call__
    await self.middleware_stack(scope, receive, send)
  File "/home/aurora/AI/venv/lib/python3.12/site-packages/starlette/middleware/errors.py", line 187, in __call__
    raise exc
  File "/home/aurora/AI/venv/lib/python3.12/site-packages/starlette/middleware/errors.py", line 165, in __call__
    await self.app(scope, receive, _send)
  File "/home/aurora/AI/venv/lib/python3.12/site-packages/starlette/middleware/exceptions.py", line 62, in __call__
    await wrap_app_handling_exceptions(self.app, conn)(scope, receive, send)
  File "/home/aurora/AI/venv/lib/python3.12/site-packages/starlette/_exception_handler.py", line 62, in wrapped_app
    raise exc
  File "/home/aurora/AI/venv/lib/python3.12/site-packages/starlette/_exception_handler.py", line 51, in wrapped_app
    await app(scope, receive, sender)
  File "/home/aurora/AI/venv/lib/python3.12/site-packages/starlette/routing.py", line 715, in __call__
    await self.middleware_stack(scope, receive, send)
  File "/home/aurora/AI/venv/lib/python3.12/site-packages/starlette/routing.py", line 735, in app
    await route.handle(scope, receive, send)
  File "/home/aurora/AI/venv/lib/python3.12/site-packages/starlette/routing.py", line 288, in handle
    await self.app(scope, receive, send)
  File "/home/aurora/AI/venv/lib/python3.12/site-packages/starlette/routing.py", line 76, in app
    await wrap_app_handling_exceptions(app, request)(scope, receive, send)
  File "/home/aurora/AI/venv/lib/python3.12/site-packages/starlette/_exception_handler.py", line 62, in wrapped_app
    raise exc
  File "/home/aurora/AI/venv/lib/python3.12/site-packages/starlette/_exception_handler.py", line 51, in wrapped_app
    await app(scope, receive, sender)
  File "/home/aurora/AI/venv/lib/python3.12/site-packages/starlette/routing.py", line 73, in app
    response = await f(request)
               ^^^^^^^^^^^^^^^^
  File "/home/aurora/AI/venv/lib/python3.12/site-packages/fastapi/routing.py", line 338, in app
    response = actual_response_class(content, **response_args)
               ^^^^^^^^^^^^^^^^^^^^^^^^^^^^^^^^^^^^^^^^^^^^^^^
  File "/home/aurora/AI/venv/lib/python3.12/site-packages/starlette/responses.py", line 178, in __init__
    super().__init__(content, status_code, headers, media_type, background)
  File "/home/aurora/AI/venv/lib/python3.12/site-packages/starlette/responses.py", line 41, in __init__
    self.body = self.render(content)
                ^^^^^^^^^^^^^^^^^^^^
  File "/home/aurora/AI/venv/lib/python3.12/site-packages/fastapi/responses.py", line 45, in render
    assert orjson is not None, "orjson must be installed to use ORJSONResponse"
           ^^^^^^^^^^^^^^^^^^
AssertionError: orjson must be installed to use ORJSONResponse
INFO:     Started server process [1300688]
INFO:     Waiting for application startup.
INFO:     Application startup complete.
INFO:     Uvicorn running on http://0.0.0.0:8000 (Press CTRL+C to quit)
ERROR:    Exception in ASGI application
Traceback (most recent call last):
  File "/home/aurora/AI/venv/lib/python3.12/site-packages/uvicorn/protocols/http/httptools_impl.py", line 401, in run_asgi
    result = await app(  # type: ignore[func-returns-value]
             ^^^^^^^^^^^^^^^^^^^^^^^^^^^^^^^^^^^^^^^^^^^^^^
  File "/home/aurora/AI/venv/lib/python3.12/site-packages/uvicorn/middleware/proxy_headers.py", line 70, in __call__
    return await self.app(scope, receive, send)
           ^^^^^^^^^^^^^^^^^^^^^^^^^^^^^^^^^^^^
  File "/home/aurora/AI/venv/lib/python3.12/site-packages/fastapi/applications.py", line 1054, in __call__
    await super().__call__(scope, receive, send)
  File "/home/aurora/AI/venv/lib/python3.12/site-packages/starlette/applications.py", line 113, in __call__
    await self.middleware_stack(scope, receive, send)
  File "/home/aurora/AI/venv/lib/python3.12/site-packages/starlette/middleware/errors.py", line 187, in __call__
    raise exc
  File "/home/aurora/AI/venv/lib/python3.12/site-packages/starlette/middleware/errors.py", line 165, in __call__
    await self.app(scope, receive, _send)
  File "/home/aurora/AI/venv/lib/python3.12/site-packages/starlette/middleware/exceptions.py", line 62, in __call__
    await wrap_app_handling_exceptions(self.app, conn)(scope, receive, send)
  File "/home/aurora/AI/venv/lib/python3.12/site-packages/starlette/_exception_handler.py", line 62, in wrapped_app
    raise exc
  File "/home/aurora/AI/venv/lib/python3.12/site-packages/starlette/_exception_handler.py", line 51, in wrapped_app
    await app(scope, receive, sender)
  File "/home/aurora/AI/venv/lib/python3.12/site-packages/starlette/routing.py", line 715, in __call__
    await self.middleware_stack(scope, receive, send)
  File "/home/aurora/AI/venv/lib/python3.12/site-packages/starlette/routing.py", line 735, in app
    await route.handle(scope, receive, send)
  File "/home/aurora/AI/venv/lib/python3.12/site-packages/starlette/routing.py", line 288, in handle
    await self.app(scope, receive, send)
  File "/home/aurora/AI/venv/lib/python3.12/site-packages/starlette/routing.py", line 76, in app
    await wrap_app_handling_exceptions(app, request)(scope, receive, send)
  File "/home/aurora/AI/venv/lib/python3.12/site-packages/starlette/_exception_handler.py", line 62, in wrapped_app
    raise exc
  File "/home/aurora/AI/venv/lib/python3.12/site-packages/starlette/_exception_handler.py", line 51, in wrapped_app
    await app(scope, receive, sender)
  File "/home/aurora/AI/venv/lib/python3.12/site-packages/starlette/routing.py", line 73, in app
    response = await f(request)
               ^^^^^^^^^^^^^^^^
  File "/home/aurora/AI/venv/lib/python3.12/site-packages/fastapi/routing.py", line 338, in app
    response = actual_response_class(content, **response_args)
               ^^^^^^^^^^^^^^^^^^^^^^^^^^^^^^^^^^^^^^^^^^^^^^^
  File "/home/aurora/AI/venv/lib/python3.12/site-packages/starlette/responses.py", line 178, in __init__
    super().__init__(content, status_code, headers, media_type, background)
  File "/home/aurora/AI/venv/lib/python3.12/site-packages/starlette/responses.py", line 41, in __init__
    self.body = self.render(content)
                ^^^^^^^^^^^^^^^^^^^^
  File "/home/aurora/AI/venv/lib/python3.12/site-packages/fastapi/responses.py", line 45, in render
    assert orjson is not None, "orjson must be installed to use ORJSONResponse"
           ^^^^^^^^^^^^^^^^^^
AssertionError: orjson must be installed to use ORJSONResponse
